Workbook

Sheet Claude Log
A1: Turn # | B1: Date | C1: User Request | D1: Action Taken | E1: Details | F1: Outcome
A2: 1 | B2: 46074 | C2: Organiser un tableau professionnel complet du voyage Brésil avec: logistique vols, hébergements, timeline Gantt, coûts par personne, budget CHF+BRL, checklist documents, contacts, et identification des trous (hébergement manquant etc.) | D2: Extrait données de 11 PDFs (vols SWISS/TAP/Azul, hôtels Booking, location Localiza). Créé 11 feuilles: Logistique Vols, Hébergements, Location Voiture, Where by Date, Timeline Gantt, Coûts par Personne, Budget Total, Trous & Alertes, Checklist Voyage, Contacts & Adresses, Claude Log. | E2: 6 vols, 4 hôtels, 1 location voiture. Taux change 6.7 BRL/CHF. Formules SUM pour totaux. Budget total estimé ~CHF 3,736. Identifié 11 alertes dont 5 urgentes: 6 nuits hébergement manquant 30/05-05/06, transport SP→Ourilândia manquant, vols Azul en espera, 0 bagage soute SWISS/TAP. | F2: Classeur complet livré. En attente des informations supplémentaires de l'utilisateur (prochain message). Trous identifiés en rouge. ⚠️ 6 nuits sans hébergement entre Canoa Quebrada et vol retour.
A3: 2 | B3: 46074 | C3: Mettre à jour les billets: 1) Nouveau vol SP→Ourilândia (Itinéraire.pdf), 2) Nouveaux vols Azul MAB→BEL (MJ5NQC) et BEL→FOR (ON3LQT) remplacent anciens non débités. 3) Mettre des dates au lieu de jours sur le Gantt. | D3: Extrait 3 nouveaux PDFs. Ajouté vol VCP→BEL→Ourilândia (Azul AD2954+AD5108, 07-08/05, réf TNG1NT/AKE4YZ). Mis à jour vols Azul: LI2NWF→MJ5NQC (R$1300.17) et ZLT7RZ→ON3LQT (R$799.14). Sièges maintenant sélectionnés. Refait le Gantt avec dates réelles. | E3: Feuilles mises à jour: Logistique Vols (7 lignes), Budget Total (+63.09 BRL), Coûts par Personne, Trous&Alertes (SP→Ourilândia marqué RÉSOLU), Timeline, Checklist, Contacts. Gantt: axe horizontal en jours avec échelle dates (J0=27/04 → J42=09/06). | F3: 7 vols au total. Budget total mis à jour: CHF ~3,746. Alerte SP→Ourilândia résolue. Restent: 6 nuits manquantes 30/05-05/06, retour Lucileide+Jhemerson, bagages Azul=0.
A4: 3 | B4: 46074 | C4: 1) Lucileide+Jhemerson rentrent en bus après 06/06 (leur logistique). 2) Gantt: ajouter partie Claudio (dès 23/05). 3) Gantt: remplacer axe 0-42 par vraies dates dd/mm. 4) Afficher durée sur les barres. | D4: Refait entièrement le Gantt avec 3 sections: CLAUDEANE (27/04→), CLAUDIO (23/05→), ENSEMBLE (25/05→). Axe horizontal en dates dd/mm (27/04 au 10/06, pas hebdomadaires). Data labels durée en blanc sur barres. Lucileide+Jhemerson marqués retour bus ~06-09/06. | E4: Chart source: I3:K17 avec 14 étapes. Axe min=46139 (27/04), max=46182 (10/06), majorUnit=7j, numberFormat=dd/mm. Série 1 (début) transparente, série 2 (durée) bleue #2E75B6 avec labels blancs. Alerte retour Lucileide+Jhemerson marquée RÉSOLU. | F4: Gantt complet avec dates + 3 sections. Alertes réduites à 3 ouvertes: 6 nuits manquantes, bagages Azul=0, vols Azul en espera.
A5: 4 | B5: 46074 | C5: Gantt bicolore: 2 barres de couleurs différentes à partir du 23/05 (rose pour Claudeane, bleu pour Claudio). Quand ensemble, les 2 barres apparaissent. | D5: Refait le Gantt avec 3 séries stackées: Début (invisible), Claudeane (#E74C8B rose), Claudio (#2E75B6 bleu). Quand les deux voyagent ensemble (Encontro Sol, ASAS, TROU, retour), les 2 barres colorées s'empilent. Labels durée en blanc, zéros masqués. | E5: Source: I3:L17 (14 étapes). Axe dates dd/MM 27/04→10/06. Légende: Claudeane + Claudio (Début masqué). Format labels: '#;#;""' pour masquer 0. Lucileide+Jhemerson bus ajouté en dernière ligne. | F5: Gantt bicolore fonctionnel. On voit clairement qui voyage quand, et quand ils sont ensemble (barres empilées rose+bleu).
A6: 5 | B6: 46074 | C6: Gantt bicolore: barres l'une SUR l'autre (pas côte à côte empilées). Chaque étape partagée = 2 lignes distinctes dans le chart. | D6: Refait le Gantt avec 18 lignes: étapes solo = 1 ligne, étapes partagées (Encontro Sol, ASAS, TROU, retour) = 2 lignes séparées [Cd] et [Cl]. Chart 580x880px. Légende Claudeane rose + Claudio bleu. | E6: Source I3:L21. Séries: Début (transparent), Claudeane (#E74C8B), Claudio (#2E75B6). Labels durée blancs, 0 masqués. Axe dates dd/MM 27/04→10/06. | F6: Gantt clair: barres roses et bleues sur lignes séparées. Visuellement, on voit qui est où et quand les deux se retrouvent.
A7: 6 | B7: 46074 | C7: Rapprocher les barres Claudeane/Claudio quand même étape (l'une sur l'autre, pas espacées). | D7: Réduit gapWidth à 0% sur le chart barStacked. Les barres sont maintenant au maximum de largeur et les lignes adjacentes (même étape [Cd]/[Cl]) se touchent. | E7: series.items[0].gapWidth = 0. Pas de paramètre overlap nécessaire car c'est entre catégories (pas entre séries dans une catégorie). | F7: Barres Claudeane et Claudio collées l'une à l'autre pour les étapes partagées. Visuellement beaucoup plus clair.
A11: 10 | B11: 46074 | C11: Utilisateur pas satisfait du Gantt mais demande de ne plus y toucher. | D11: Aucune modification. Gantt laissé en l'état (2 swim lanes séparées Claudeane/Claudio). | E11: Limitation Excel: impossible d'avoir dans un seul chart barStacked des barres groupées (et non empilées) pour les étapes partagées tout en gardant l'offset invisible pour le début des dates. Le format idéal nécessiterait un outil de visualisation externe (ex: Google Sheets timeline, ou un vrai diagramme de Gantt). | F11: Gantt non modifié. Le reste du classeur (vols, hébergements, budget, alertes, checklist, contacts) est complet et fonctionnel.
A12: 11 | B12: 46074 | C12: User wants a detailed description of every sheet (data + structure) to recreate the spreadsheet as an HTML page hosted via Git for sharing with other travelers. | D12: Read all 12 sheets exhaustively, compiled complete Markdown documentation | E12: Exported Description_Complete_Classeur_Bresil_2026.md (424 lines, ~24KB). Covers all 12 sheets: Logistique Vols (7 flights), Hébergements (4 hotels), Location Voiture (Localiza SUV), Where by Date (23 daily entries), Timeline Gantt (2 versions with 3 charts), Coûts par Personne (Claudio + Claudeane), Budget Total (formulas + grand total), Trous & Alertes (11 alerts), Checklist (16 items), Contacts (20+ entries). Includes meta-info: color palette (#1F4E79, #2E75B6, #E74C8B), typography, exchange rate, traveler profiles. | F12: Complete MD file exported. User can use this as data source for HTML/Git page reconstruction.
A13: 12 | B13: 46074 | C13: User couldn't find the exported .md file | D13: Re-exported the MD file and explained where to find it | E13: File re-exported via bash OUTPUT_DIR. Offered to put content directly in Excel sheet if download still not visible. | F13: Awaiting user confirmation they found the file.
A14: 13 | B14: 46074 | C14: User couldn't find MD download. Asked to put description in a new sheet instead. | D14: Created '📄 Description HTML' sheet (sheetId 17) with 283 rows of complete data | E14: All 10 onglets documented row-by-row with exact data values, including user's recent changes (C16=311.80 CHF for VCP→Ourilândia, updated sous-total Claudeane=1310.35 CHF, checklist modifications). Includes: meta-info (voyageurs, devises, palette couleurs, typo), 7 vols, 4 hôtels, location voiture détaillée, Where by Date 23 entrées, Gantt 3 charts + étapes, coûts par personne, budget total avec formules, 11 alertes, checklist 14 items, 20+ contacts. Formatted with color-coded sections matching original spreadsheet. | F14: Sheet '📄 Description HTML' ready. User can copy all data for HTML/Git reconstruction.
A15: 14 | B15: 46074 | C15: User asked to fix dates (especially VCP→BEL was wrong) and make sheets dynamic so changes propagate automatically. | D15: Fixed 4 wrong dates in Logistique Vols, 8 serial numbers in Where by Date, added 16+ inter-sheet formulas | E15: DATES FIXED: D3 (46208→46149 = 07/05), F3 (46239→46150 = 08/05), D5/D6 (46148→46178 = 05/06). Applied dd/MM/yyyy format to all date columns. Fixed A6,A7,A19-A24 serial numbers in Where by Date. FORMULAS ADDED: D2,D3,D4,D6,D7,D11 reference '📋 Logistique Vols' for flight info. C9-C16,C11 reference '🏨 Hébergements' for hotel names. C23-D24 reference return flight times. Now changing a hotel name or flight time in source sheets auto-updates Where by Date. | F15: All dates corrected. Where by Date now dynamically linked to Logistique Vols and Hébergements. Description HTML also updated.
A16: 15 | B16: 46074 | C16: User asked if all sheets are linked and have consistent data. | D16: Full cross-sheet audit via Python: dates, prices, totals, formulas | E16: AUDIT RESULT: All data consistent across sheets (dates, prices, totals all match). Where by Date has 16+ dynamic formulas linking to source sheets. Gantt dates correct but static (=DATE()). Budget/Costs prices static but accurate. Offered to add remaining price formulas to Budget/Costs sheets. | F16: Data 100% consistent. Some sheets still use static values instead of formulas. Awaiting user decision on adding more cross-sheet links.
... A22: 22 | B22: 46074 | C22: Reprendre et terminer la régénération complète de l'onglet Description HTML (interrompue à la ligne 50 lors de la session précédente). | D22: Vidé l'ancien contenu (50 lignes avec dates sérielles cassées). Réécrit entièrement en 5 blocs (255 lignes): Méta-infos, Vols (7), Hébergements (5 incl. Pousada Bangalô), Location Voiture, Where by Date (23 entrées), Gantt résumé, Coûts/Personne, Budget Total (Grand Total 4 314.97 CHF), Trous&Alertes (13), Checklist (16 items), Contacts. | E22: Toutes dates écrites en texte lisible (dd/MM/yyyy ou dd/MM). Heures en texte (HH:MM). Format numérique @ pour éviter auto-conversion Excel. Correction des dates Where by Date forcées en texte. Colonnes A-F redimensionnées (200-280 pts). Headers colorés (#1F4E79, #2E75B6, #FF0000, #D6E4F0). | F22: Onglet Description HTML complet et à jour avec toutes les données du classeur, prêt pour reconstitution HTML/Git.

Sheet 🗄️ BD Source
A1: 🗄️ BASE DE DONNÉES SOURCE — VOYAGE BRÉSIL 2026
A3: VOLS
A4: ID | B4: Passager(s) | C4: Itinéraire | D4: Date Départ | E4: Heure Départ | F4: Date Arrivée | G4: Heure Arrivée | H4: Compagnie | I4: N° Vols | J4: Classe | K4: Réf. Réservation | L4: Bagage Cabine | M4: Bagage Soute | N4: Sièges | O4: Prix CHF | P4: Prix BRL | Q4: Statut Paiement | R4: Nb Pax | S4: Notes
A5: V1 | B5: Claudeane | C5: GVA → ZRH → GRU (São Paulo) | D5: =DATE(2026,4,27) -> 46139 | E5: =TIME(20,5,0) -> 0.83680556 | F5: =DATE(2026,4,28) -> 46140 | G5: =TIME(5,25,0) -> 0.22569444 | H5: SWISS | I5: LX2819 + LX92 | J5: Economy Light (K) | K5: YS3VET | L5: 1 main (8kg, 118lcm) | M5: ⚠️ 0 SOUTE | N5: Non sélectionnés | O5: 290.15 | Q5: ✅ Payé - MC ****4753 | R5: 1 | S5: Terminal 1 GVA
A6: V2 | B6: Claudeane | C6: VCP (São Paulo) → BEL → Ourilândia do Norte | D6: =DATE(2026,5,7) -> 46149 | E6: =TIME(21,45,0) -> 0.90625 | F6: =DATE(2026,5,8) -> 46150 | G6: =TIME(9,45,0) -> 0.40625 | H6: Azul (via Trip.com) | I6: AD2954 + AD5108 | J6: Economy | K6: TNG1NT / AKE4YZ | L6: 1 pers + 1 cabine (10kg) | M6: ✅ 1 soute (23kg) | N6: Non sélectionnés | O6: 311.8 | Q6: ⚠️ En Espera (Trip.com) | R6: 1 | S6: Escale Belém
A7: V3 | B7: Claudio | C7: GVA → Lisbonne → FOR (Fortaleza) | D7: =DATE(2026,5,23) -> 46165 | E7: =TIME(13,0,0) -> 0.54166667 | F7: =DATE(2026,5,23) -> 46165 | G7: =TIME(21,20,0) -> 0.88888889 | H7: TAP Portugal | I7: TP941 + TP35 | J7: Économique | K7: XR2CPW | L7: 1 petit + 1 cabine (10kg) | M7: ⚠️ 0 SOUTE | N7: Non sélectionnés | O7: 845.81 | Q7: ✅ Payé - Booking.com (A/R) | R7: 1 | S7: Billet A/R
A8: V4 | B8: Claudio | C8: FOR → Lisbonne → GVA (retour) | D8: =DATE(2026,6,5) -> 46178 | E8: =TIME(22,50,0) -> 0.95138889 | F8: =DATE(2026,6,6) -> 46179 | G8: =TIME(17,30,0) -> 0.72916667 | H8: TAP Portugal | I8: TP36 + TP942 | J8: Économique | K8: XR2CPW | L8: 1 petit + 1 cabine (10kg) | M8: ⚠️ 0 SOUTE | N8: 10A (TP36) / 7E (TP942) | O8: 0 | Q8: ✅ Inclus A/R (845.81 CHF) | R8: 1 | S8: Retour inclus dans V3
A9: V5 | B9: Claudeane | C9: FOR → Lisbonne → GVA (retour) | D9: =DATE(2026,6,5) -> 46178 | E9: =TIME(22,50,0) -> 0.95138889 | F9: =DATE(2026,6,6) -> 46179 | G9: =TIME(17,30,0) -> 0.72916667 | H9: TAP Portugal | I9: TP36 + TP942 | J9: Économique | K9: XR85TH | L9: 1 petit + 1 cabine (10kg) | M9: ✅ 1 soute (23kg) | N9: 10C (TP36) / 7F (TP942) | O9: 552.15 | Q9: ✅ Payé - Booking.com | R9: 1
A10: V6 | B10: Claudeane + Lucileide + Jhemerson | C10: MAB (Marabá) → BEL (Belém) | D10: =DATE(2026,5,25) -> 46167 | E10: =TIME(14,50,0) -> 0.61805556 | F10: =DATE(2026,5,25) -> 46167 | G10: =TIME(15,55,0) -> 0.66319444 | H10: Azul | I10: AD 4210 | J10: — | K10: MJ5NQC | L10: 0 (non sélectionné) | M10: 0 (non sélectionné) | N10: 11D / 11E / 11F | P10: 1300.17 | Q10: ⚠️ EN ESPERA - 3 pax | R10: 3 | S10: Remplace LI2NWF
A11: V7 | B11: Claudeane + Lucileide + Jhemerson | C11: BEL (Belém) → FOR (Fortaleza) | D11: =DATE(2026,5,25) -> 46167 | E11: =TIME(18,0,0) -> 0.75 | F11: =DATE(2026,5,25) -> 46167 | G11: =TIME(19,55,0) -> 0.82986111 | H11: Azul | I11: AD 4101 | J11: — | K11: ON3LQT | L11: 0 (non sélectionné) | M11: 0 (non sélectionné) | N11: 11A / 11B / 11C | P11: 799.14 | Q11: ⚠️ EN ESPERA - 3 pax | R11: 3 | S11: Remplace ZLT7RZ
A13: HÉBERGEMENTS
A14: ID | B14: Voyageur(s) | C14: Établissement | D14: Ville | E14: Date CheckIn | F14: Heure CheckIn | G14: Date CheckOut | H14: Heure CheckOut | I14: Nuits | J14: Chambre | K14: Petit-déj. | L14: Prix CHF | M14: Prix BRL | N14: Prépaiement | O14: Annulation gratuite | P14: Réf. Confirmation | Q14: Parking | R14: WiFi | S14: GPS
A15: H1 | B15: Claudeane (+ fille) | C15: Free Palace Hotel | D15: São Paulo | E15: =DATE(2026,4,27) -> 46139 | F15: =TIME(13,0,0) -> 0.54166667 | G15: =DATE(2026,4,30) -> 46142 | H15: =TIME(12,0,0) -> 0.5 | I15: 3 | J15: Lits Jumeaux Standard | K15: ✅ OUI | L15: 103 | M15: 691.65 | N15: ❌ NON requis | O15: 24/04/2026 | P15: 5474140188 | Q15: R$ 35/jour | R15: Gratuit | S15: S 023° 33.693, W 46° 37.977
A16: H2 | B16: Claudio (seul) | C16: Maly Boutique Hotel | D16: Fortaleza (Praia do Futuro) | E16: =DATE(2026,5,23) -> 46165 | F16: =TIME(14,0,0) -> 0.58333333 | G16: =DATE(2026,5,25) -> 46167 | H16: =TIME(12,0,0) -> 0.5 | I16: 2 | J16: Suite avec Balcon (vue jardin/piscine) | K16: ✅ OUI | L16: 116 | M16: 779.62 | N16: ✅ OUI - Prépaiement total | O16: 17/05/2026 | P16: 5987193612 | Q16: Pas de parking | R16: Gratuit | S16: S 003° 43.880, W 38° 27.466
A17: H3 | B17: Claudio + Claudeane + Lucileide + Jhemerson | C17: Hotel Encontro do Sol | D17: Fortaleza (Meireles) | E17: =DATE(2026,5,25) -> 46167 | F17: =TIME(13,30,0) -> 0.5625 | G17: =DATE(2026,5,27) -> 46169 | H17: =TIME(12,0,0) -> 0.5 | I17: 2 | J17: Quadruple Classique | K17: ✅ OUI | L17: 125 | M17: 840 | N17: ❌ NON PAYÉ — 50% à payer avant le 09/04/2026 (15j avant annul. 24/04) | O17: 24/04/2026 | P17: 5331265550 | Q17: Pas de parking | R17: Gratuit | S17: S 003° 43.418, W 38° 30.401
A18: H4 | B18: Claudio + Claudeane + Lucileide + Jhemerson | C18: ASAS DEL MAR - SUITES | D18: Canoa Quebrada | E18: =DATE(2026,5,27) -> 46169 | F18: =TIME(14,0,0) -> 0.58333333 | G18: =DATE(2026,5,30) -> 46172 | H18: =TIME(12,0,0) -> 0.5 | I18: 3 | J18: Quadruple - Vue sur Mer | K18: Non mentionné | L18: 294 | M18: 1968 | N18: ❌ NON PAYÉ — Conditions à vérifier. Si 50%: payer avant le 04/05/2026 (15j avant annul. 19/05) | O18: 19/05/2026 | P18: 6862089551 | Q18: Gratuit (public) | R18: Gratuit | S18: S 004° 31.671, W 37° 41.874
A19: H5 | B19: Claudio + Claudeane + Lucileide + Jhemerson | C19: Pousada Bangalô | D19: Jericoacoara | E19: =DATE(2026,6,1) -> 46174 | F19: =TIME(12,0,0) -> 0.5 | G19: =DATE(2026,6,3) -> 46176 | H19: =TIME(12,0,0) -> 0.5 | I19: 2 | J19: 2× Double/Twin Standard | K19: ✅ OUI | L19: 129 | M19: 861.12 | N19: ❌ NON PAYÉ — 50% à payer avant le 11/05/2026 (15j avant annul. 26/05) | O19: 26/05/2026 | P19: 5620.348.709 | Q19: Public (supplément possible) | R19: Gratuit | S19: S 002° 47.867, W 40° 30.843
A21: TRANSPORT
A22: ID | B22: Conducteur(s) | C22: Véhicule | D22: Agence | E22: Date Début | F22: Heure Début | G22: Date Fin | H22: Heure Fin | I22: Durée (jours) | J22: Prix BRL | K22: Pré-autorisation BRL | L22: Statut Paiement | M22: Réf. | N22: Adresse Agence | O22: Notes
A23: T1 | B23: Claudio + conducteur additionnel | C23: SUV AUTOMATIQUE | D23: Localiza | E23: =DATE(2026,5,23) -> 46165 | F23: =TIME(22,0,0) -> 0.91666667 | G23: =DATE(2026,6,5) -> 46178 | H23: =TIME(18,0,0) -> 0.75 | I23: 13 | J23: 3132.3 | K23: 2500 | L23: ⚠️ À PAYER à la prise | M23: MO49499YVQBC | N23: AV SENADOR CARLOS JEREISSATI 21, SERRINHA, FORTALEZA, CE | O23: Annulation gratuite >48h. 24h/24.
A25: CONTACTS
A26: ID | B26: Organisme | C26: Téléphone | D26: Adresse / Web | E26: Notes
A27: C1 | B27: SWISS Service Center | C27: +41 (0) 848 700 700 | D27: swiss.com/webcheckin | E27: Réf YS3VET
A28: C2 | B28: TAP Portugal | C28: — | D28: flytap.com | E28: Réf XR2CPW / XR85TH
A29: C3 | B29: Azul Linhas Aéreas | C29: 4003-1118 / 0800 887 1118 | D29: voeazul.com.br | E29: Réf MJ5NQC + ON3LQT + TNG1NT
A30: C4 | B30: Booking.com (assist. FR) | C30: 0445 111 635 | D30: your.booking.com | E30: +33 1 57 32 92 09
A31: C5 | B31: Free Palace Hotel | C31: +55 11 3271 8596 | D31: RUA TAMANDARE 246, Liberdade, SP | E31: GPS: S023°33.693 W46°37.977
A32: C6 | B32: Maly Boutique Hotel | C32: +55 85 99111 0568 | D32: Av Clóvis Arrais Maia 2790, Fortaleza | E32: GPS: S003°43.880 W38°27.466
A33: C7 | B33: Hotel Encontro do Sol | C33: +55 85 3031 6222 | D33: Rua Monsenhor Bruno 122, Meireles | E33: GPS: S003°43.418 W38°30.401
A34: C8 | B34: ASAS DEL MAR | C34: +55 85 99856 8461 | D34: DT SITIO ESTEVAO, Canoa Quebrada | E34: GPS: S004°31.671 W37°41.874
A35: C9 | B35: Localiza Rent a Car | C35: App Localiza (FAST) | D35: Aéroport Fortaleza | E35: Réf MO49499YVQBC
A36: C10 | B36: Police (Polícia Militar) | C36: 190
A37: C11 | B37: SAMU (ambulance) | C37: 192
A38: C12 | B38: Pompiers (Bombeiros) | C38: 193
A39: C13 | B39: Ambassade Suisse | C39: +55 61 3443 5500 | D39: Brasília
A40: C14 | B40: Claudio (personnel) | C40: 41762470577
A41: C15 | B41: Pousada Bangalô (Jericoacoara) | C41: +55 88 99904 5258 | D41: Rua Novo Jeri, S/N, Jericoacoara, CEP 62598-000 | E41: GPS: S002°47.867 W40°30.843. Réf 5620.348.709
A42: VOYAGEURS
A43: ID | B43: Nom | C43: Rôle | D43: Date Début Voyage | E43: Date Fin Voyage | F43: Retour par
A44: P1 | B44: Claudeane | C44: Épouse (brésilienne) | D44: =DATE(2026,4,27) -> 46139 | E44: =DATE(2026,6,6) -> 46179 | F44: ✈️ Avion
...

Sheet 📋 Logistique Vols
A1: N° | B1: Passager(s) | C1: Itinéraire | D1: Date Départ | E1: Heure Départ | F1: Date Arrivée | G1: Heure Arrivée | H1: Compagnie | I1: N° Vols | J1: Classe | K1: Réf. Réservation | L1: Bagage Cabine | M1: Bagage Soute | N1: Sièges | O1: Prix (CHF) | P1: Prix (BRL) | Q1: Statut Paiement
A2: 1 | B2: ='🗄️ BD Source'!B5 -> Claudeane | C2: ='🗄️ BD Source'!C5 -> GVA → ZRH → GRU (São Paulo) | D2: ='🗄️ BD Source'!D5 -> 46139 | E2: ='🗄️ BD Source'!E5 -> 0.83680556 | F2: ='🗄️ BD Source'!F5 -> 46140 | G2: ='🗄️ BD Source'!G5 -> 0.22569444 | H2: ='🗄️ BD Source'!H5 -> SWISS | I2: ='🗄️ BD Source'!I5 -> LX2819 + LX92 | ... Q2: ='🗄️ BD Source'!Q5 -> ✅ Payé - MC ****4753
A3: 2 | B3: ='🗄️ BD Source'!B6 -> Claudeane | C3: ='🗄️ BD Source'!C6 -> VCP (São Paulo) → BEL → Ourilândia do Norte | D3: ='🗄️ BD Source'!D6 -> 46149 | E3: ='🗄️ BD Source'!E6 -> 0.90625 | F3: ='🗄️ BD Source'!F6 -> 46150 | G3: ='🗄️ BD Source'!G6 -> 0.40625 | H3: ='🗄️ BD Source'!H6 -> Azul (via Trip.com) | I3: ='🗄️ BD Source'!I6 -> AD2954 + AD5108 | ... Q3: ='🗄️ BD Source'!Q6 -> ⚠️ En Espera (Trip.com)
A4: 3 | B4: ='🗄️ BD Source'!B7 -> Claudio | C4: ='🗄️ BD Source'!C7 -> GVA → Lisbonne → FOR (Fortaleza) | D4: ='🗄️ BD Source'!D7 -> 46165 | E4: ='🗄️ BD Source'!E7 -> 0.54166667 | F4: ='🗄️ BD Source'!F7 -> 46165 | G4: ='🗄️ BD Source'!G7 -> 0.88888889 | H4: ='🗄️ BD Source'!H7 -> TAP Portugal | I4: ='🗄️ BD Source'!I7 -> TP941 + TP35 | ... Q4: ='🗄️ BD Source'!Q7 -> ✅ Payé - Booking.com (A/R)
A5: 4 | B5: ='🗄️ BD Source'!B8 -> Claudio | C5: ='🗄️ BD Source'!C8 -> FOR → Lisbonne → GVA (retour) | D5: ='🗄️ BD Source'!D8 -> 46178 | E5: ='🗄️ BD Source'!E8 -> 0.95138889 | F5: ='🗄️ BD Source'!F8 -> 46179 | G5: ='🗄️ BD Source'!G8 -> 0.72916667 | H5: ='🗄️ BD Source'!H8 -> TAP Portugal | I5: ='🗄️ BD Source'!I8 -> TP36 + TP942 | ... Q5: ='🗄️ BD Source'!Q8 -> ✅ Inclus A/R (845.81 CHF)
A6: 5 | B6: ='🗄️ BD Source'!B9 -> Claudeane | C6: ='🗄️ BD Source'!C9 -> FOR → Lisbonne → GVA (retour) | D6: ='🗄️ BD Source'!D9 -> 46178 | E6: ='🗄️ BD Source'!E9 -> 0.95138889 | F6: ='🗄️ BD Source'!F9 -> 46179 | G6: ='🗄️ BD Source'!G9 -> 0.72916667 | H6: ='🗄️ BD Source'!H9 -> TAP Portugal | I6: ='🗄️ BD Source'!I9 -> TP36 + TP942 | ... Q6: ='🗄️ BD Source'!Q9 -> ✅ Payé - Booking.com
A7: 6 | B7: ='🗄️ BD Source'!B10 -> Claudeane + Lucileide + Jhemerson | C7: ='🗄️ BD Source'!C10 -> MAB (Marabá) → BEL (Belém) | D7: ='🗄️ BD Source'!D10 -> 46167 | E7: ='🗄️ BD Source'!E10 -> 0.61805556 | F7: ='🗄️ BD Source'!F10 -> 46167 | G7: ='🗄️ BD Source'!G10 -> 0.66319444 | H7: ='🗄️ BD Source'!H10 -> Azul | I7: ='🗄️ BD Source'!I10 -> AD 4210 | ... Q7: ='🗄️ BD Source'!Q10 -> ⚠️ EN ESPERA - 3 pax
A8: 7 | B8: ='🗄️ BD Source'!B11 -> Claudeane + Lucileide + Jhemerson | C8: ='🗄️ BD Source'!C11 -> BEL (Belém) → FOR (Fortaleza) | D8: ='🗄️ BD Source'!D11 -> 46167 | E8: ='🗄️ BD Source'!E11 -> 0.75 | F8: ='🗄️ BD Source'!F11 -> 46167 | G8: ='🗄️ BD Source'!G11 -> 0.82986111 | H8: ='🗄️ BD Source'!H11 -> Azul | I8: ='🗄️ BD Source'!I11 -> AD 4101 | ... Q8: ='🗄️ BD Source'!Q11 -> ⚠️ EN ESPERA - 3 pax

Sheet 🏨 Hébergements
A1: N° | B1: Établissement | C1: Ville | D1: Check-in | E1: Check-out | F1: Nuits | G1: Voyageur(s) | H1: Chambre | I1: Petit-déj. | J1: Prix CHF | K1: Prix BRL | L1: Prépaiement | M1: Annulation gratuite jusqu'au | N1: Réf. Confirmation | O1: Parking | P1: WiFi
A2: 1 | B2: ='🗄️ BD Source'!C15 -> Free Palace Hotel | C2: ='🗄️ BD Source'!D15 -> São Paulo | D2: =TEXT('🗄️ BD Source'!E15,"jj/MM/aaaa")&" "&TEXT('🗄️ BD Source'!F15,"HH:mm") -> 27/04/2026 13:00 | E2: =TEXT('🗄️ BD Source'!G15,"jj/MM/aaaa")&" "&TEXT('🗄️ BD Source'!H15,"HH:mm") -> 30/04/2026 12:00 | F2: ='🗄️ BD Source'!I15 -> 3 | G2: ='🗄️ BD Source'!B15 -> Claudeane (+ fille) | H2: ='🗄️ BD Source'!J15 -> Lits Jumeaux Standard | I2: ='🗄️ BD Source'!K15 -> ✅ OUI | J2: ='🗄️ BD Source'!L15 -> 103 | K2: ='🗄️ BD Source'!M15 -> 691.65 | L2: ='🗄️ BD Source'!N15 -> ❌ NON requis | M2: ='🗄️ BD Source'!O15 -> 24/04/2026 | N2: ='🗄️ BD Source'!P15 -> 5474140188 | O2: ='🗄️ BD Source'!Q15 -> R$ 35/jour | P2: ='🗄️ BD Source'!R15 -> Gratuit
A3: 2 | B3: ='🗄️ BD Source'!C16 -> Maly Boutique Hotel | C3: ='🗄️ BD Source'!D16 -> Fortaleza (Praia do Futuro) | D3: =TEXT('🗄️ BD Source'!E16,"jj/MM/aaaa")&" "&TEXT('🗄️ BD Source'!F16,"HH:mm") -> 23/05/2026 14:00 | E3: =TEXT('🗄️ BD Source'!G16,"jj/MM/aaaa")&" "&TEXT('🗄️ BD Source'!H16,"HH:mm") -> 25/05/2026 12:00 | F3: ='🗄️ BD Source'!I16 -> 2 | G3: ='🗄️ BD Source'!B16 -> Claudio (seul) | H3: ='🗄️ BD Source'!J16 -> Suite avec Balcon (vue jardin/piscine) | I3: ='🗄️ BD Source'!K16 -> ✅ OUI | J3: ='🗄️ BD Source'!L16 -> 116 | K3: ='🗄️ BD Source'!M16 -> 779.62 | L3: ='🗄️ BD Source'!N16 -> ✅ OUI - Prépaiement total | M3: ='🗄️ BD Source'!O16 -> 17/05/2026 | N3: ='🗄️ BD Source'!P16 -> 5987193612 | O3: ='🗄️ BD Source'!Q16 -> Pas de parking | P3: ='🗄️ BD Source'!R16 -> Gratuit
A4: 3 | B4: ='🗄️ BD Source'!C17 -> Hotel Encontro do Sol | C4: ='🗄️ BD Source'!D17 -> Fortaleza (Meireles) | D4: =TEXT('🗄️ BD Source'!E17,"jj/MM/aaaa")&" "&TEXT('🗄️ BD Source'!F17,"HH:mm") -> 25/05/2026 13:30 | E4: =TEXT('🗄️ BD Source'!G17,"jj/MM/aaaa")&" "&TEXT('🗄️ BD Source'!H17,"HH:mm") -> 27/05/2026 12:00 | F4: ='🗄️ BD Source'!I17 -> 2 | G4: ='🗄️ BD Source'!B17 -> Claudio + Claudeane + Lucileide + Jhemerson | H4: ='🗄️ BD Source'!J17 -> Quadruple Classique | I4: ='🗄️ BD Source'!K17 -> ✅ OUI | J4: ='🗄️ BD Source'!L17 -> 125 | K4: ='🗄️ BD Source'!M17 -> 840 | L4: ='🗄️ BD Source'!N17 -> ❌ NON PAYÉ — 50% à payer avant le 09/04/2026 (15j avant annul. 24/04) | M4: ='🗄️ BD Source'!O17 -> 24/04/2026 | N4: ='🗄️ BD Source'!P17 -> 5331265550 | O4: ='🗄️ BD Source'!Q17 -> Pas de parking | P4: ='🗄️ BD Source'!R17 -> Gratuit
A5: 4 | B5: ='🗄️ BD Source'!C18 -> ASAS DEL MAR - SUITES | C5: ='🗄️ BD Source'!D18 -> Canoa Quebrada | D5: =TEXT('🗄️ BD Source'!E18,"jj/MM/aaaa")&" "&TEXT('🗄️ BD Source'!F18,"HH:mm") -> 27/05/2026 14:00 | E5: =TEXT('🗄️ BD Source'!G18,"jj/MM/aaaa")&" "&TEXT('🗄️ BD Source'!H18,"HH:mm") -> 30/05/2026 12:00 | F5: ='🗄️ BD Source'!I18 -> 3 | G5: ='🗄️ BD Source'!B18 -> Claudio + Claudeane + Lucileide + Jhemerson | H5: ='🗄️ BD Source'!J18 -> Quadruple - Vue sur Mer | I5: ='🗄️ BD Source'!K18 -> Non mentionné | J5: ='🗄️ BD Source'!L18 -> 294 | K5: ='🗄️ BD Source'!M18 -> 1968 | L5: ='🗄️ BD Source'!N18 -> ❌ NON PAYÉ — Conditions à vérifier. Si 50%: payer avant le 04/05/2026 (15j avant annul. 19/05) | M5: ='🗄️ BD Source'!O18 -> 19/05/2026 | N5: ='🗄️ BD Source'!P18 -> 6862089551 | O5: ='🗄️ BD Source'!Q18 -> Gratuit (public) | P5: ='🗄️ BD Source'!R18 -> Gratuit
A6: 5 | B6: ='🗄️ BD Source'!C19 -> Pousada Bangalô | C6: ='🗄️ BD Source'!D19 -> Jericoacoara | D6: =TEXT('🗄️ BD Source'!E19,"jj/MM/aaaa")&" "&TEXT('🗄️ BD Source'!F19,"HH:mm") -> 01/06/2026 12:00 | E6: =TEXT('🗄️ BD Source'!G19,"jj/MM/aaaa")&" "&TEXT('🗄️ BD Source'!H19,"HH:mm") -> 03/06/2026 12:00 | F6: ='🗄️ BD Source'!I19 -> 2 | G6: ='🗄️ BD Source'!B19 -> Claudio + Claudeane + Lucileide + Jhemerson | H6: ='🗄️ BD Source'!J19 -> 2× Double/Twin Standard | I6: ='🗄️ BD Source'!K19 -> ✅ OUI | J6: ='🗄️ BD Source'!L19 -> 129 | K6: ='🗄️ BD Source'!M19 -> 861.12 | L6: ='🗄️ BD Source'!N19 -> ❌ NON PAYÉ — 50% à payer avant le 11/05/2026 (15j avant annul. 26/05) | M6: ='🗄️ BD Source'!O19 -> 26/05/2026 | N6: ='🗄️ BD Source'!P19 -> 5620.348.709 | O6: ='🗄️ BD Source'!Q19 -> Public (supplément possible) | P6: ='🗄️ BD Source'!R19 -> Gratuit

Sheet 🚗 Location Voiture
A1: 🚗 LOCATION VOITURE - LOCALIZA
A3: Référence | B3: MO49499YVQBC
A4: Véhicule | B4: SUV AUTOMATIQUE
A5: Durée | B5: 13 jours
A6: Conducteur | B6: Claudio Stadelmann + Conducteur additionnel
A8: PRISE DU VÉHICULE
A9: Date | B9: 23/05/2026 à 22h00
A10: Agence | B10: AEROPORTO INTERN - FORTALEZA
A11: Adresse | B11: AV SENADOR CARLOS JEREISSATI 21, SERRINHA, FORTALEZA, CE
A12: Horaires agence | B12: 00:00 - 23:59 (24h/24)
A14: RETOUR DU VÉHICULE
A15: Date | B15: 05/06/2026 à 18h00
A16: Agence | B16: AEROPORTO INTERN - FORTALEZA (même agence)
A18: DÉTAIL DES COÛTS (BRL)
A19: Diárias (location) | B19: 13 x R$ 110.95 | C19: 1442.35
A20: Neutraliza (carbone) | B20: 13 x R$ 13.00 | C20: 169
A21: Condutor Adicional | B21: 13 x R$ 61.88 | C21: 804.44
A22: Condutor Jovem | B22: 13 x R$ 0.13 | C22: 1.69
A23: Limpeza Garantida (-40%) | B23: 1 x R$ 34.95 | C23: 34.95
A24: Proteção Total Avarias | B24: 13 x R$ 710.32 | C24: 9234.16
A26: Seguro de Terceiros | B26: 13 x R$ 17.95 | C26: 233.35
A27: Proteção do Carro | B27: 13 x R$ 17.52 | C27: 227.76
A28: Taxa de aluguel | B28: Taxe fixe | C28: 408.56
A29: TOTAL LOCATION | C29: 3132.3
A31: Pré-autorisation | B31: R$ 2,500.00 (remboursée après clôture contrat)
A32: Statut paiement | B32: ⚠️ À PAYER à la prise (pré-autorisation)
A33: Note | B33: Annulation gratuite >48h avant. <48h = 20% total. No-show = 30% total.

Sheet 📅 Where by Date
A1: Date | B1: Jour | C1: Claudio | D1: Claudeane | E1: Lucileide + Jhemerson
A2: 27/04 | B2: Dim | C2: 🏠 Genève | D2: ="✈️ "&'🗄️ BD Source'!C5&" (dép "&TEXT('🗄️ BD Source'!E5,"HH:mm")&")" -> ✈️ GVA → ZRH → GRU (São Paulo) (dép 20:05) | E2: —
A3: 28/04 | B3: Lun | C3: 🏠 Genève | D3: ="📍Arrivée São Paulo "&TEXT('🗄️ BD Source'!G5,"HH:mm")&" → "&'🗄️ BD Source'!C15 -> 📍Arrivée São Paulo 05:25 → Free Palace Hotel | E3: —
A4: 29/04 | B4: Mar | C4: 🏠 Genève | D4: ="🏨 "&'🗄️ BD Source'!C15&", São Paulo" -> 🏨 Free Palace Hotel, São Paulo | E4: —
A5: 30/04-06/05 | B5: ... | C5: 🏠 Genève | D5: 📍 Chez la fille à São Paulo (~1 semaine) | E5: —
A6: 07/05 | B6: Jeu | C6: 🏠 Genève | D6: ="✈️ "&'🗄️ BD Source'!C6&" (dép "&TEXT('🗄️ BD Source'!E6,"HH:mm")&") "&'🗄️ BD Source'!H6&" "&'🗄️ BD Source'!I6 -> ✈️ VCP (São Paulo) → BEL → Ourilândia do Norte (dép 21:45) Azul (via Trip.com) AD2954 + AD5108 | E6: —
A7: 08/05 | B7: Ven | C7: 🏠 Genève | D7: ="✈️ BEL→Ourilândia (arr "&TEXT('🗄️ BD Source'!G6,"HH:mm")&") "&'🗄️ BD Source'!I6 -> ✈️ BEL→Ourilândia (arr 09:45) AD2954 + AD5108 | E7: —
A8: 09/05-22/05 | B8: ... | C8: 🏠 Genève | D8: 📍 Ourilândia do Norte (chez famille, ~2 sem) | E8: 📍 Ourilândia do Norte (chez eux)
A9: 23/05 | B9: Sam soir | C9: ="🏨 "&'🗄️ BD Source'!C16&", Fortaleza" -> 🏨 Maly Boutique Hotel, Fortaleza | D9: 📍 Ourilândia do Norte | E9: 📍 Ourilândia do Norte
A10: 24/05 | B10: Dim | C10: ="🏨 "&'🗄️ BD Source'!C16&", Fortaleza" -> 🏨 Maly Boutique Hotel, Fortaleza | D10: ⚠️ Ourilândia → Marabá? (transport manquant) | E10: ⚠️ Ourilândia → Marabá?
A11: 25/05 | B11: Lun | C11: ="🏨 Check-out "&'🗄️ BD Source'!C16&" → "&'🗄️ BD Source'!C17&" "&TEXT('🗄️ BD Source'!F17,"HH:mm") -> 🏨 Check-out Maly Boutique Hotel → Hotel Encontro do Sol 13:30 | D11: ="✈️ MAB→BEL "&TEXT('🗄️ BD Source'!E10,"HH:mm")&" / BEL→FOR "&TEXT('🗄️ BD Source'!E11,"HH:mm")&" (arr "&TEXT('🗄️ BD Source'!G11,"HH:mm")&")" -> ✈️ MAB→BEL 14:50 / BEL→FOR 18:00 (arr 19:55) | E11: ="✈️ MAB→BEL→FOR (même vols)" -> ✈️ MAB→BEL→FOR (même vols)
A12: 25/05 | B12: Lun soir | C12: ="🏨 "&'🗄️ BD Source'!C17&", Fortaleza" -> 🏨 Hotel Encontro do Sol, Fortaleza | D12: ="🏨 "&'🗄️ BD Source'!C17&", Fortaleza" -> 🏨 Hotel Encontro do Sol, Fortaleza | E12: ="🏨 "&'🗄️ BD Source'!C17 -> 🏨 Hotel Encontro do Sol
A13: 26/05 | B13: Mar | C13: ="🏨 "&'🗄️ BD Source'!C17&", Fortaleza" -> 🏨 Hotel Encontro do Sol, Fortaleza | D13: ="🏨 "&'🗄️ BD Source'!C17&", Fortaleza" -> 🏨 Hotel Encontro do Sol, Fortaleza | E13: ="🏨 "&'🗄️ BD Source'!C17 -> 🏨 Hotel Encontro do Sol
A14: 27/05 | B14: Mer | C14: ="🚗 Fortaleza → Canoa Quebrada ("&'🗄️ BD Source'!C18&")" -> 🚗 Fortaleza → Canoa Quebrada (ASAS DEL MAR - SUITES) | D14: ="🚗 → "&'🗄️ BD Source'!C18&", Canoa Quebrada" -> 🚗 → ASAS DEL MAR - SUITES, Canoa Quebrada | E14: ="🚗 → "&'🗄️ BD Source'!C18 -> 🚗 → ASAS DEL MAR - SUITES
A15: 28/05 | B15: Jeu | C15: ="🏖️ "&'🗄️ BD Source'!C18&", Canoa Quebrada" -> 🏖️ ASAS DEL MAR - SUITES, Canoa Quebrada | D15: ="🏖️ "&'🗄️ BD Source'!C18&", Canoa Quebrada" -> 🏖️ ASAS DEL MAR - SUITES, Canoa Quebrada | E15: ="🏖️ "&'🗄️ BD Source'!C18 -> 🏖️ ASAS DEL MAR - SUITES
A16: 29/05 | B16: Ven | C16: ="🏖️ "&'🗄️ BD Source'!C18&", Canoa Quebrada" -> 🏖️ ASAS DEL MAR - SUITES, Canoa Quebrada | D16: ="🏖️ "&'🗄️ BD Source'!C18&", Canoa Quebrada" -> 🏖️ ASAS DEL MAR - SUITES, Canoa Quebrada | E16: ="🏖️ "&'🗄️ BD Source'!C18 -> 🏖️ ASAS DEL MAR - SUITES
A17: 30/05 | B17: Sam | C17: ⚠️ Check-out ASAS → HÉBERGEMENT MANQUANT | D17: ⚠️ HÉBERGEMENT MANQUANT | E17: ⚠️ HÉBERGEMENT MANQUANT
A18: 31/05 | B18: Dim | C18: ⚠️ HÉBERGEMENT MANQUANT | D18: ⚠️ HÉBERGEMENT MANQUANT | E18: ⚠️ HÉBERGEMENT MANQUANT
A19: 01/06 | B19: Lun | C19: ="🏨 "&'🗄️ BD Source'!C19&", "&'🗄️ BD Source'!D19 -> 🏨 Pousada Bangalô, Jericoacoara | D19: ="🏨 "&'🗄️ BD Source'!C19&", "&'🗄️ BD Source'!D19 -> 🏨 Pousada Bangalô, Jericoacoara | E19: ="🏨 "&'🗄️ BD Source'!C19 -> 🏨 Pousada Bangalô
A20: 02/06 | B20: Mar | C20: ="🏨 "&'🗄️ BD Source'!C19&", "&'🗄️ BD Source'!D19 -> 🏨 Pousada Bangalô, Jericoacoara | D20: ="🏨 "&'🗄️ BD Source'!C19&", "&'🗄️ BD Source'!D19 -> 🏨 Pousada Bangalô, Jericoacoara | E20: ="🏨 "&'🗄️ BD Source'!C19 -> 🏨 Pousada Bangalô
A21: 03/06 | B21: Mer | C21: ⚠️ HÉBERGEMENT MANQUANT (check-out Pousada) | D21: ⚠️ HÉBERGEMENT MANQUANT | E21: ⚠️ HÉBERGEMENT MANQUANT
A22: 04/06 | B22: Jeu | C22: ⚠️ HÉBERGEMENT MANQUANT | D22: ⚠️ HÉBERGEMENT MANQUANT | E22: ⚠️ HÉBERGEMENT MANQUANT
A23: 05/06 | B23: Ven | C23: ="🚗 Retour Localiza "&TEXT('🗄️ BD Source'!H23,"HH:mm")&" → ✈️ FOR→LIS→GVA "&TEXT('🗄️ BD Source'!E8,"HH:mm") -> 🚗 Retour Localiza 18:00 → ✈️ FOR→LIS→GVA 22:50 | D23: ="✈️ FOR→LIS→GVA "&TEXT('🗄️ BD Source'!E9,"HH:mm") -> ✈️ FOR→LIS→GVA 22:50 | E23: 🚌 Retour en bus (leur logistique)
A24: 06/06 | B24: Sam | C24: ="📍 Arrivée GVA "&TEXT('🗄️ BD Source'!G8,"HH:mm")&" 🏠" -> 📍 Arrivée GVA 17:30 🏠 | D24: ="📍 Arrivée GVA "&TEXT('🗄️ BD Source'!G9,"HH:mm")&" 🏠" -> 📍 Arrivée GVA 17:30 🏠 | E24: 🚌 En route retour bus

Sheet 📊 Timeline Gantt (2)
A1: 📅 TIMELINE GANTT - VOYAGE BRÉSIL 2026
A3: Étape | E3: Étape | F3: Début | G3: Durée (j) | I3: CLAUDEANE | J3: Début | K3: Durée | M3: CLAUDIO | N3: Début | O3: Durée
A4: CLAUDEANE | B4: Début | C4: Fin | E4: CLAUDEANE | I4: ✈ GVA→SP | J4: ='🗄️ BD Source'!D5 -> 46139 | K4: ='🗄️ BD Source'!F5-'🗄️ BD Source'!D5+1 -> 2 | M4: ✈ GVA→FOR | N4: ='🗄️ BD Source'!D7 -> 46165 | O4: 1
A5: ✈️ Vol GVA→São Paulo | B5: =TEXT('🗄️ BD Source'!D5,"jj/MM") -> 27/04 | C5: =TEXT('🗄️ BD Source'!F5,"jj/MM") -> 28/04 | E5: ✈ Vol GVA→São Paulo | F5: =DATE(2026,4,27) -> 46139 | G5: 2 | I5: 🏨 Free Palace (3n) | J5: ='🗄️ BD Source'!E15 -> 46139 | K5: ='🗄️ BD Source'!I15 -> 3 | M5: 🚗 Localiza SUV (13j) | N5: ='🗄️ BD Source'!E23 -> 46165 | O5: ='🗄️ BD Source'!I23 -> 13
A6: 🏨 Free Palace Hotel, São Paulo | B6: =TEXT('🗄️ BD Source'!E15,"jj/MM") -> 27/04 | C6: =TEXT('🗄️ BD Source'!G15,"jj/MM") -> 30/04 | E6: 🏨 Free Palace SP (3n) | F6: =DATE(2026,4,27) -> 46139 | G6: 3 | I6: 📍 Chez fille SP | J6: ='🗄️ BD Source'!G15 -> 46142 | K6: =INT('🗄️ BD Source'!D6)-INT('🗄️ BD Source'!G15) -> 7 | M6: 🏨 Maly Boutique (2n) | N6: ='🗄️ BD Source'!E16 -> 46165 | O6: ='🗄️ BD Source'!I16 -> 2
A7: 📍 Chez fille São Paulo | B7: =TEXT('🗄️ BD Source'!G15,"jj/MM") -> 30/04 | C7: =TEXT('🗄️ BD Source'!D6,"jj/MM") -> 07/05 | E7: 📍 Chez fille São Paulo | F7: =DATE(2026,4,30) -> 46142 | G7: 7 | I7: ✈ VCP→Ourilândia | J7: ='🗄️ BD Source'!D6 -> 46149 | K7: ='🗄️ BD Source'!F6-'🗄️ BD Source'!D6+1 -> 2 | M7: 🏨 Encontro Sol (2n) | N7: ='🗄️ BD Source'!E17 -> 46167 | O7: ='🗄️ BD Source'!I17 -> 2
A8: ✈️ VCP→BEL→Ourilândia (AD2954+5108) | B8: =TEXT('🗄️ BD Source'!D6,"jj/MM") -> 07/05 | C8: =TEXT('🗄️ BD Source'!F6,"jj/MM") -> 08/05 | E8: ✈ Vol VCP→Ourilândia | F8: =DATE(2026,5,7) -> 46149 | G8: 2 | I8: 📍 Ourilândia (17j) | J8: ='🗄️ BD Source'!F6 -> 46150 | K8: ='🗄️ BD Source'!D10-'🗄️ BD Source'!F6 -> 17 | M8: 🏖 ASAS Canoa (3n) | N8: ='🗄️ BD Source'!E18 -> 46169 | O8: ='🗄️ BD Source'!I18 -> 3
A9: 📍 Ourilândia do Norte (famille) | B9: =TEXT('🗄️ BD Source'!F6,"jj/MM") -> 08/05 | C9: ~24/05 | E9: 📍 Ourilândia (famille) | F9: =DATE(2026,5,8) -> 46150 | G9: 17 | I9: ✈ MAB→BEL→FOR | J9: ='🗄️ BD Source'!D10 -> 46167 | K9: 1 | M9: ⚠ TROU 6n! | N9: ='🗄️ BD Source'!G18 -> 46172 | O9: =INT('🗄️ BD Source'!D8)-INT('🗄️ BD Source'!G18) -> 6
A10: ✈️ MAB→BEL→FOR (avec sœur+neveu) | B10: =TEXT('🗄️ BD Source'!D10,"jj/MM") -> 25/05 | C10: =TEXT('🗄️ BD Source'!F11,"jj/MM") -> 25/05 | I10: 🏨 Encontro Sol (2n) | J10: ='🗄️ BD Source'!E17 -> 46167 | K10: ='🗄️ BD Source'!I17 -> 2 | M10: 🚗 Retour Localiza | N10: ='🗄️ BD Source'!D8 -> 46178 | O10: 1
A11: 🏨 Hotel Encontro do Sol, Fortaleza | B11: =TEXT('🗄️ BD Source'!E17,"jj/MM") -> 25/05 | C11: =TEXT('🗄️ BD Source'!G17,"jj/MM") -> 27/05 | E11: CLAUDIO | I11: 🏖 ASAS Canoa (3n) | J11: ='🗄️ BD Source'!E18 -> 46169 | K11: ='🗄️ BD Source'!I18 -> 3 | M11: ✈ FOR→GVA | N11: ='🗄️ BD Source'!D8 -> 46178 | O11: ='🗄️ BD Source'!F8-'🗄️ BD Source'!D8+1 -> 2
A12: 🏖️ ASAS DEL MAR, Canoa Quebrada | B12: =TEXT('🗄️ BD Source'!E18,"jj/MM") -> 27/05 | C12: =TEXT('🗄️ BD Source'!G18,"jj/MM") -> 30/05 | E12: ✈ Vol GVA→Fortaleza | F12: =DATE(2026,5,23) -> 46165 | G12: 1 | I12: ⚠ TROU 6n! | J12: ='🗄️ BD Source'!G18 -> 46172 | K12: =INT('🗄️ BD Source'!D8)-INT('🗄️ BD Source'!G18) -> 6
A13: ⚠️ HÉBERGEMENT MANQUANT | B13: =TEXT('🗄️ BD Source'!G18,"jj/MM") -> 30/05 | C13: =TEXT('🗄️ BD Source'!D8,"jj/MM") -> 05/06 | E13: 🚗 Localiza SUV (13j) | F13: =DATE(2026,5,23) -> 46165 | G13: 13 | I13: ✈ FOR→GVA | J13: ='🗄️ BD Source'!D8 -> 46178 | K13: ='🗄️ BD Source'!F8-'🗄️ BD Source'!D8+1 -> 2
A14: ✈️ Vol FOR→GVA | B14: =TEXT('🗄️ BD Source'!D9,"jj/MM") -> 05/06 | C14: =TEXT('🗄️ BD Source'!F9,"jj/MM") -> 06/06 | E14: 🏨 Maly Boutique (2n) | F14: =DATE(2026,5,23) -> 46165 | G14: 2 | I14: 🚌 Luc.+Jh. bus | J14: ='🗄️ BD Source'!F8 -> 46179 | K14: 3
A15: ✈️ Vol GVA→Fortaleza | B15: =TEXT('🗄️ BD Source'!D7,"jj/MM") -> 23/05 | C15: =TEXT('🗄️ BD Source'!F7,"jj/MM") -> 23/05
A16: 🚗 Location Localiza (SUV, 13j) | B16: =TEXT('🗄️ BD Source'!E23,"jj/MM") -> 23/05 | C16: =TEXT('🗄️ BD Source'!G23,"jj/MM") -> 05/06 | E16: ENSEMBLE (4 pers)
A17: 🏨 Maly Boutique Hotel, Fortaleza | B17: =TEXT('🗄️ BD Source'!E16,"jj/MM") -> 23/05 | C17: =TEXT('🗄️ BD Source'!G16,"jj/MM") -> 25/05 | E17: ✈ MAB→BEL→FOR (3 pax) | F17: =DATE(2026,5,25) -> 46167 | G17: 1
A18: 🏨 Hotel Encontro do Sol, Fortaleza | B18: =TEXT('🗄️ BD Source'!E17,"jj/MM") -> 25/05 | C18: =TEXT('🗄️ BD Source'!G17,"jj/MM") -> 27/05 | E18: 🏨 Encontro Sol (2n) | F18: =DATE(2026,5,25) -> 46167 | G18: 2
A19: 🏖️ ASAS DEL MAR, Canoa Quebrada | B19: =TEXT('🗄️ BD Source'!E18,"jj/MM") -> 27/05 | C19: =TEXT('🗄️ BD Source'!G18,"jj/MM") -> 30/05 | E19: 🏖 ASAS Canoa Q. (3n) | F19: =DATE(2026,5,27) -> 46169 | G19: 3
A20: ⚠️ HÉBERGEMENT MANQUANT | B20: =TEXT('🗄️ BD Source'!G18,"jj/MM") -> 30/05 | C20: =TEXT('🗄️ BD Source'!D8,"jj/MM") -> 05/06 | E20: ⚠ TROU HÉBERG. (6n!) | F20: =DATE(2026,5,30) -> 46172 | G20: 6
A21: 🚗 Retour Localiza + ✈️ Vol FOR→GVA | B21: =TEXT('🗄️ BD Source'!D8,"jj/MM") -> 05/06 | C21: =TEXT('🗄️ BD Source'!F8,"jj/MM") -> 06/06 | E21: ✈ Vol FOR→GVA retour | F21: =DATE(2026,6,5) -> 46178 | G21: 2
E22: 🚌 Lucil.+Jhem. retour bus | F22: =DATE(2026,6,6) -> 46179 | G22: 3
A23: LUCILEIDE + JHEMERSON
A24: ✈️ MAB→BEL→FOR (avec Claudeane) | B24: =TEXT('🗄️ BD Source'!D10,"jj/MM") -> 25/05 | C24: =TEXT('🗄️ BD Source'!F11,"jj/MM") -> 25/05
A25: 🏨 Hotel Encontro do Sol, Fortaleza | B25: =TEXT('🗄️ BD Source'!E17,"jj/MM") -> 25/05 | C25: =TEXT('🗄️ BD Source'!G17,"jj/MM") -> 27/05
A26: 🏖️ ASAS DEL MAR, Canoa Quebrada | B26: =TEXT('🗄️ BD Source'!E18,"jj/MM") -> 27/05 | C26: =TEXT('🗄️ BD Source'!G18,"jj/MM") -> 30/05
A27: ⚠️ HÉBERGEMENT MANQUANT | B27: =TEXT('🗄️ BD Source'!G18,"jj/MM") -> 30/05 | C27: =TEXT('🗄️ BD Source'!D8,"jj/MM") -> 05/06
A28: 🚌 Retour en bus (leur logistique) | B28: ~06/06 | C28: ~09/06

Sheet 📊 Timeline Gantt
A1: 📅 TIMELINE GANTT - VOYAGE BRÉSIL 2026
A3: Étape | E3: Étape | F3: Début | G3: Durée (j) | I3: Étape | J3: Début | K3: Claudeane | L3: Claudio
A4: CLAUDEANE | B4: Début | C4: Fin | E4: CLAUDEANE | I4: ✈ GVA→SP | J4: ='🗄️ BD Source'!D5 -> 46139 | K4: ='🗄️ BD Source'!F5-'🗄️ BD Source'!D5+1 -> 2 | L4: 0
A5: ✈️ Vol GVA→São Paulo | B5: =TEXT('🗄️ BD Source'!D5,"jj/MM") -> 27/04 | C5: =TEXT('🗄️ BD Source'!F5,"jj/MM") -> 28/04 | E5: ✈ Vol GVA→São Paulo | F5: ='🗄️ BD Source'!D5 -> 46139 | G5: ='🗄️ BD Source'!F5-'🗄️ BD Source'!D5+1 -> 2 | I5: 🏨 Free Palace (3n) | J5: ='🗄️ BD Source'!E15 -> 46139 | K5: ='🗄️ BD Source'!I15 -> 3 | L5: 0
A6: 🏨 Free Palace Hotel, São Paulo | B6: =TEXT('🗄️ BD Source'!E15,"jj/MM") -> 27/04 | C6: =TEXT('🗄️ BD Source'!G15,"jj/MM") -> 30/04 | E6: 🏨 Free Palace SP (3n) | F6: ='🗄️ BD Source'!E15 -> 46139 | G6: ='🗄️ BD Source'!I15 -> 3 | I6: 📍 Chez fille SP | J6: ='🗄️ BD Source'!G15 -> 46142 | K6: =INT('🗄️ BD Source'!D6)-INT('🗄️ BD Source'!G15) -> 7 | L6: 0
A7: 📍 Chez fille São Paulo | B7: =TEXT('🗄️ BD Source'!G15,"jj/MM") -> 30/04 | C7: =TEXT('🗄️ BD Source'!D6,"jj/MM") -> 07/05 | E7: 📍 Chez fille São Paulo | F7: ='🗄️ BD Source'!G15 -> 46142 | G7: =INT('🗄️ BD Source'!D6)-INT('🗄️ BD Source'!G15) -> 7 | I7: ✈ VCP→Ourilândia | J7: ='🗄️ BD Source'!D6 -> 46149 | K7: ='🗄️ BD Source'!F6-'🗄️ BD Source'!D6+1 -> 2 | L7: 0
A8: ✈️ VCP→BEL→Ourilândia (AD2954+5108) | B8: =TEXT('🗄️ BD Source'!D6,"jj/MM") -> 07/05 | C8: =TEXT('🗄️ BD Source'!F6,"jj/MM") -> 08/05 | E8: ✈ Vol VCP→Ourilândia | F8: ='🗄️ BD Source'!D6 -> 46149 | G8: ='🗄️ BD Source'!F6-'🗄️ BD Source'!D6+1 -> 2 | I8: 📍 Ourilândia (famille) | J8: ='🗄️ BD Source'!F6 -> 46150 | K8: ='🗄️ BD Source'!D10-'🗄️ BD Source'!F6 -> 17 | L8: 0
A9: 📍 Ourilândia do Norte (famille) | B9: =TEXT('🗄️ BD Source'!F6,"jj/MM") -> 08/05 | C9: ~24/05 | E9: 📍 Ourilândia (famille) | F9: ='🗄️ BD Source'!F6 -> 46150 | G9: ='🗄️ BD Source'!D10-'🗄️ BD Source'!F6 -> 17 | I9: ✈ GVA→FOR | J9: ='🗄️ BD Source'!D7 -> 46165 | K9: 0 | L9: 1
A10: ✈️ MAB→BEL→FOR (avec sœur+neveu) | B10: =TEXT('🗄️ BD Source'!D10,"jj/MM") -> 25/05 | C10: =TEXT('🗄️ BD Source'!F11,"jj/MM") -> 25/05 | I10: 🚗 Localiza SUV (13j) | J10: ='🗄️ BD Source'!E23 -> 46165 | K10: 0 | L10: ='🗄️ BD Source'!I23 -> 13
A11: 🏨 Hotel Encontro do Sol, Fortaleza | B11: =TEXT('🗄️ BD Source'!E17,"jj/MM") -> 25/05 | C11: =TEXT('🗄️ BD Source'!G17,"jj/MM") -> 27/05 | E11: CLAUDIO | I11: 🏨 Maly Boutique (2n) | J11: ='🗄️ BD Source'!E16 -> 46165 | K11: 0 | L11: ='🗄️ BD Source'!I16 -> 2
A12: 🏖️ ASAS DEL MAR, Canoa Quebrada | B12: =TEXT('🗄️ BD Source'!E18,"jj/MM") -> 27/05 | C12: =TEXT('🗄️ BD Source'!G18,"jj/MM") -> 30/05 | E12: ✈ Vol GVA→Fortaleza | F12: ='🗄️ BD Source'!D7 -> 46165 | G12: 1 | I12: ✈ MAB→BEL→FOR | J12: ='🗄️ BD Source'!D10 -> 46167 | K12: 1 | L12: 0
A13: ⚠️ HÉBERGEMENT MANQUANT | B13: =TEXT('🗄️ BD Source'!G18,"jj/MM") -> 30/05 | C13: =TEXT('🗄️ BD Source'!D8,"jj/MM") -> 05/06 | E13: 🚗 Localiza SUV (13j) | F13: ='🗄️ BD Source'!E23 -> 46165 | G13: ='🗄️ BD Source'!I23 -> 13 | I13: 🏨 Encontro Sol (2n) | J13: ='🗄️ BD Source'!E17 -> 46167 | K13: ='🗄️ BD Source'!I17 -> 2 | L13: ='🗄️ BD Source'!I17 -> 2
A14: ✈️ Vol FOR→GVA | B14: =TEXT('🗄️ BD Source'!D9,"jj/MM") -> 05/06 | C14: =TEXT('🗄️ BD Source'!F9,"jj/MM") -> 06/06 | E14: 🏨 Maly Boutique (2n) | F14: ='🗄️ BD Source'!E16 -> 46165 | G14: ='🗄️ BD Source'!I16 -> 2 | I14: 🏖 ASAS Canoa (3n) | J14: ='🗄️ BD Source'!E18 -> 46169 | K14: ='🗄️ BD Source'!I18 -> 3 | L14: ='🗄️ BD Source'!I18 -> 3
A15: ✈️ Vol GVA→Fortaleza | B15: =TEXT('🗄️ BD Source'!D7,"jj/MM") -> 23/05 | C15: =TEXT('🗄️ BD Source'!F7,"jj/MM") -> 23/05 | I15: ⚠ TROU HÉBERG. (6n!) | J15: ='🗄️ BD Source'!G18 -> 46172 | K15: =INT('🗄️ BD Source'!D8)-INT('🗄️ BD Source'!G18) -> 6 | L15: =INT('🗄️ BD Source'!D8)-INT('🗄️ BD Source'!G18) -> 6
A16: 🚗 Location Localiza (SUV, 13j) | B16: =TEXT('🗄️ BD Source'!E23,"jj/MM") -> 23/05 | C16: =TEXT('🗄️ BD Source'!G23,"jj/MM") -> 05/06 | E16: ENSEMBLE (4 pers) | I16: ✈ FOR→GVA retour | J16: ='🗄️ BD Source'!D8 -> 46178 | K16: ='🗄️ BD Source'!F8-'🗄️ BD Source'!D8+1 -> 2 | L16: ='🗄️ BD Source'!F8-'🗄️ BD Source'!D8+1 -> 2
A17: 🏨 Maly Boutique Hotel, Fortaleza | B17: =TEXT('🗄️ BD Source'!E16,"jj/MM") -> 23/05 | C17: =TEXT('🗄️ BD Source'!G16,"jj/MM") -> 25/05 | E17: ✈ MAB→BEL→FOR (3 pax) | F17: ='🗄️ BD Source'!D10 -> 46167 | G17: 1 | I17: 🚌 Luc.+Jh. bus | J17: ='🗄️ BD Source'!F8 -> 46179 | K17: 3 | L17: 0
A18: 🏨 Hotel Encontro do Sol, Fortaleza | B18: =TEXT('🗄️ BD Source'!E17,"jj/MM") -> 25/05 | C18: =TEXT('🗄️ BD Source'!G17,"jj/MM") -> 27/05 | E18: 🏨 Encontro Sol (2n) | F18: ='🗄️ BD Source'!E17 -> 46167 | G18: ='🗄️ BD Source'!I17 -> 2
A19: 🏖️ ASAS DEL MAR, Canoa Quebrada | B19: =TEXT('🗄️ BD Source'!E18,"jj/MM") -> 27/05 | C19: =TEXT('🗄️ BD Source'!G18,"jj/MM") -> 30/05 | E19: 🏖 ASAS Canoa Q. (3n) | F19: ='🗄️ BD Source'!E18 -> 46169 | G19: ='🗄️ BD Source'!I18 -> 3
A20: ⚠️ HÉBERGEMENT MANQUANT | B20: =TEXT('🗄️ BD Source'!G18,"jj/MM") -> 30/05 | C20: =TEXT('🗄️ BD Source'!D8,"jj/MM") -> 05/06 | E20: ⚠ TROU HÉBERG. (6n!) | F20: ='🗄️ BD Source'!G18 -> 46172 | G20: =INT('🗄️ BD Source'!D8)-INT('🗄️ BD Source'!G18) -> 6
A21: 🚗 Retour Localiza + ✈️ Vol FOR→GVA | B21: =TEXT('🗄️ BD Source'!D8,"jj/MM") -> 05/06 | C21: =TEXT('🗄️ BD Source'!F8,"jj/MM") -> 06/06 | E21: ✈ Vol FOR→GVA retour | F21: ='🗄️ BD Source'!D8 -> 46178 | G21: ='🗄️ BD Source'!F8-'🗄️ BD Source'!D8+1 -> 2
E22: 🚌 Lucil.+Jhem. retour bus | F22: ='🗄️ BD Source'!F8 -> 46179 | G22: 3
A23: LUCILEIDE + JHEMERSON | B23: Début | C23: Fin
A24: ✈️ MAB→BEL→FOR (avec Claudeane) | B24: =TEXT('🗄️ BD Source'!D10,"jj/MM") -> 25/05 | C24: =TEXT('🗄️ BD Source'!F11,"jj/MM") -> 25/05
A25: 🏨 Hotel Encontro do Sol, Fortaleza | B25: =TEXT('🗄️ BD Source'!E17,"jj/MM") -> 25/05 | C25: =TEXT('🗄️ BD Source'!G17,"jj/MM") -> 27/05
A26: 🏖️ ASAS DEL MAR, Canoa Quebrada | B26: =TEXT('🗄️ BD Source'!E18,"jj/MM") -> 27/05 | C26: =TEXT('🗄️ BD Source'!G18,"jj/MM") -> 30/05
A27: ⚠️ HÉBERGEMENT MANQUANT | B27: =TEXT('🗄️ BD Source'!G18,"jj/MM") -> 30/05 | C27: =TEXT('🗄️ BD Source'!D8,"jj/MM") -> 05/06
A28: 🚌 Retour en bus (leur logistique) | B28: ~06/06 | C28: ~09/06

Sheet 💰 Coûts par Personne
A1: 💰 COÛTS PAR PERSONNE
A3: Catégorie | B3: Détail | C3: CHF | D3: BRL | E3: Payé? | F3: Notes
A4: CLAUDIO
A5: Vol | B5: GVA→FOR A/R (TAP) | C5: ='🗄️ BD Source'!O7 -> 845.81 | E5: ✅ OUI | F5: Booking.com, réf XR2CPW
A6: Hôtel | B6: Maly Boutique, 2 nuits | C6: ='🗄️ BD Source'!L16 -> 116 | D6: ='🗄️ BD Source'!M16 -> 779.62 | E6: ✅ Prépayé | F6: 1 pers, suite balcon
A7: Hôtel | B7: Encontro do Sol, 2 nuits (1/4) | C7: ='🗄️ BD Source'!L17/4 -> 31.25 | D7: ='🗄️ BD Source'!M17/4 -> 210 | E7: ⚠️ 50% | F7: 4 pers, part 1/4 = R$210
A8: Hôtel | B8: ASAS DEL MAR, 3 nuits (1/4) | C8: ='🗄️ BD Source'!L18/4 -> 73.5 | D8: ='🗄️ BD Source'!M18/4 -> 492 | E8: ❌ Non payé — 50% avant 09/04 | F8: 4 pers, part 1/4 = R$492
A9: Voiture | B9: Localiza SUV 13 jours | D9: ='🗄️ BD Source'!J23 -> 3132.3 | E9: ❌ Non payé — vérifier, 50% avant 04/05 | F9: Pré-auth R$2500 à la prise
A10: Hôtel | B10: Pousada Bangalô, 2 nuits (1/4) | C10: ='🗄️ BD Source'!L19/4 -> 32.25 | D10: ='🗄️ BD Source'!M19/4 -> 215.28 | E10: ❌ Non payé — 50% avant 11/05 | F10: 4 pers, part 1/4
A11: SOUS-TOTAL CLAUDIO | C11: =SUM(C5:C10) -> 1098.81 | D11: =SUM(D5:D10) -> 4829.2
A13: CLAUDEANE
A14: Vol | B14: GVA→GRU (SWISS aller) | C14: ='🗄️ BD Source'!O5 -> 290.15 | E14: ✅ OUI | F14: MC ****4753, réf YS3VET
A15: Vol | B15: FOR→GVA (TAP retour) | C15: ='🗄️ BD Source'!O9 -> 552.15 | E15: ✅ OUI | F15: Booking.com, réf XR85TH
A16: Vol | B16: MAB→BEL→FOR (Azul, 1/3) | D16: =('🗄️ BD Source'!P10+'🗄️ BD Source'!P11)/3 -> 699.77 | E16: ⚠️ En espera | F16: NOUVEAU: R$(1300.17+799.14)/3 = R$699.77. Réf MJ5NQC + ON3LQT
A17: Vol | B17: VCP→BEL→Ourilândia (Azul/Trip.com) | C17: ='🗄️ BD Source'!O6 -> 311.8 | E17: ⚠️ En espera | F17: Réf TNG1NT/AKE4YZ, prix non précisé dans docs
A18: Hôtel | B18: Free Palace São Paulo (1/2) | C18: ='🗄️ BD Source'!L15/2 -> 51.5 | D18: ='🗄️ BD Source'!M15/2 -> 345.825 | E18: ❌ Non payé | F18: 2 pers, part 1/2
A19: Hôtel | B19: Encontro do Sol (1/4) | C19: ='🗄️ BD Source'!L17/4 -> 31.25 | D19: ='🗄️ BD Source'!M17/4 -> 210 | E19: ❌ Non payé — 50% avant 09/04 | F19: 4 pers, part 1/4
A20: Hôtel | B20: ASAS DEL MAR (1/4) | C20: ='🗄️ BD Source'!L18/4 -> 73.5 | D20: ='🗄️ BD Source'!M18/4 -> 492 | E20: ❌ Non payé — vérifier, 50% avant 04/05 | F20: 4 pers, part 1/4
A21: Hôtel | B21: Pousada Bangalô, 2 nuits (1/4) | C21: ='🗄️ BD Source'!L19/4 -> 32.25 | D21: ='🗄️ BD Source'!M19/4 -> 215.28 | E21: ❌ Non payé — 50% avant 11/05 | F21: 4 pers, part 1/4
A23: SOUS-TOTAL CLAUDEANE | C23: =SUM(C14:C21) -> 1342.6 | D23: =SUM(D14:D21) -> 1962.875

Sheet 💰 Budget Total
A1: 💰 BUDGET TOTAL - VOYAGE BRÉSIL 2026
A3: Catégorie | B3: Montant CHF | C3: Montant BRL | D3: Statut
A4: VOLS INTERNATIONAUX
A5: Claudeane: GVA→GRU (SWISS) | B5: ='🗄️ BD Source'!O5 -> 290.15 | D5: ✅ Payé
A6: Claudio: GVA→FOR A/R (TAP) | B6: ='🗄️ BD Source'!O7 -> 845.81 | D6: ✅ Payé
A7: Claudeane: FOR→GVA (TAP) | B7: ='🗄️ BD Source'!O9 -> 552.15 | D7: ✅ Payé
A8: VOLS DOMESTIQUES BRÉSIL
A9: Claudeane: VCP→BEL→Ourilândia (Azul/Trip.com) | D9: ⚠️ En espera (prix non dans docs)
A10: VCP→BEL→Ourilândia (Azul/Trip.com) | B10: ='🗄️ BD Source'!O6 -> 311.8 | D10: ✅ Payé
A11: 3 pax: MAB→BEL (Azul) - NOUVEAU MJ5NQC | C11: ='🗄️ BD Source'!P10 -> 1300.17 | D11: ✅ Payé
A12: 3 pax: BEL→FOR (Azul) - NOUVEAU ON3LQT | C12: ='🗄️ BD Source'!P11 -> 799.14 | D12: ✅ Payé
A13: HÉBERGEMENTS
A14: Free Palace Hotel (3 nuits) | B14: ='🗄️ BD Source'!L15 -> 103 | C14: ='🗄️ BD Source'!M15 -> 691.65 | D14: ❌ Non payé
A15: Maly Boutique Hotel (2 nuits) | B15: ='🗄️ BD Source'!L16 -> 116 | C15: ='🗄️ BD Source'!M16 -> 779.62 | D15: ✅ Prépayé
A16: Hotel Encontro do Sol (2 nuits) | B16: ='🗄️ BD Source'!L17 -> 125 | C16: ='🗄️ BD Source'!M17 -> 840 | D16: ⚠️ 50% prépayé
A17: ASAS DEL MAR (3 nuits) | B17: ='🗄️ BD Source'!L18 -> 294 | C17: ='🗄️ BD Source'!M18 -> 1968 | D17: ❌ Non payé — 50% avant 09/04
A18: Pousada Bangalô (2 nuits) | B18: ='🗄️ BD Source'!L19 -> 129 | C18: ='🗄️ BD Source'!M19 -> 861.12 | D18: ❌ Non payé — vérifier conditions, 50% avant 04/05
A19: LOCATION VOITURE | D19: ❌ Non payé — 50% avant 11/05
A20: Localiza SUV 13 jours | C20: ='🗄️ BD Source'!J23 -> 3132.3 | D20: ❌ À payer
A22: TOTAUX
A23: Total CHF direct | B23: =SUM(B5:B20) -> 2766.91
A24: Total BRL | C24: =SUM(C5:C20) -> 10372
A25: Taux de change estimé (1 CHF = x BRL) | B25: ='🗄️ BD Source'!B50 -> 6.7 | C25: ← Modifier ce taux si besoin
A26: Total BRL converti en CHF | B26: =C24/B25 -> 1548.0597
A27: 💰 GRAND TOTAL ESTIMÉ (CHF) | B27: =B23+B26 -> 4314.9697

Sheet ⚠️ Trous & Alertes
A1: ⚠️ TROUS & ALERTES IDENTIFIÉS
A3: Priorité | B3: Alerte | C3: Concerne | D3: Action requise
A4: 🔴 URGENT | B4: 4 NUITS HÉBERGEMENT MANQUANT (03/06 → 05/06) — Réduit de 6 à 4 grâce à Pousada Bangalô (01-03/06) | C4: TOUS (4 pers) | D4: Réserver encore 2 nuits (03-05/06) entre Pousada Bangalô et vol retour!
A5: 🔴 URGENT | B5: Vols Azul EN ESPERA (MAB→BEL MJ5NQC + BEL→FOR ON3LQT) | C5: Claudeane + Lucileide + Jhemerson | D5: Nouvelles réservations (anciennes LI2NWF/ZLT7RZ non débitées). Vérifier confirmation. Bagages = 0!
A6: ✅ RÉSOLU | B6: Transport São Paulo → Ourilândia do Norte → BILLET TROUVÉ | C6: Claudeane | D6: Azul AD2954+AD5108 le 07-08/05, réf TNG1NT/AKE4YZ (Trip.com). 1 soute 23kg inclus ✅
A7: 🔴 URGENT | B7: Vols Azul EN ESPERA (MAB→BEL + BEL→FOR) | C7: Claudeane + Lucileide + Jhemerson | D7: Vérifier statut confirmation. Bagages et sièges = 0!
A8: ✅ RÉSOLU | B8: Retour Lucileide + Jhemerson: retour en BUS après le 06/06 | C8: Lucileide + Jhemerson | D8: Gèrent leur propre logistique retour en bus. Pas besoin de billet avion.
A9: 🟠 ATTENTION | B9: Claudeane: 0 BAGAGE SOUTE GVA→GRU (SWISS Economy Light) | C9: Claudeane | D9: Acheter franchise bagage soute SWISS ou voyager ultra-léger. Tarif Light = 0 bagage!
A10: 🟠 ATTENTION | B10: Claudio: 0 BAGAGE SOUTE (TAP aller ET retour) | C10: Claudio | D10: Acheter franchise bagage soute TAP ou vérifier si inclus. Confirmation dit AUCUN.
A11: 🟠 ATTENTION | B11: Azul: Bagages ET sièges = 0 pour les 3 passagers | C11: Claudeane + Lucileide + Jhemerson | D11: Sélectionner bagages et sièges sur app Azul ou site.
A12: 🟡 INFO | B12: Hotel Encontro do Sol: 50% prépaiement par virement bancaire | C12: Claudio | D12: Contacter hôtel pour infos virement + communiquer heure arrivée.
A13: 🟡 INFO | B13: Claudio: Sièges non sélectionnés sur vol ALLER (TAP GVA→FOR) | C13: Claudio | D13: Sélectionner sièges TAP aller (TP941 + TP35). Retour OK: 10A/7E.
A14: 🟡 INFO | B14: Claudeane: Sièges non sélectionnés GVA→GRU (SWISS) | C14: Claudeane | D14: Sélectionner sièges SWISS LX2819 + LX92.
... A16: ✅ PARTIEL | B16: Pousada Bangalô réservée 01-03/06 → Gap réduit de 6 à 4 nuits (reste 03-05/06) | C16: TOUS | D16: Réf 5620.348.709. CHF 129 / R$ 861.12. Encore 2 nuits à réserver.

Sheet Feuil2

Sheet ✅ Checklist Voyage
A1: ✅ CHECKLIST DOCUMENTS VOYAGE
A3: ☐ Fait? | B3: Voyageur | C3: Document / Action | D3: Détails | E3: Date limite
A4: DOCUMENTS
A5: ☐ | B5: Claudio | C5: Passeport valide | D5: Vérifier validité > 6 mois après retour (06/06/2026) | E5: Avant départ
A6: ☐ | B6: Claudeane | C6: Passeport + titre de séjour CH | D6: Brésilienne - vérifier titre de séjour CH valide au retour | E6: Avant départ
A7: ☐ | B7: Tous | C7: Copies documents (numérique) | D7: Photos passeports, billets, confirmations dans téléphone + cloud | E7: Avant départ
A8: VOLS
A9: ☐ | B9: Claudeane | C9: Check-in SWISS LX2819+LX92 | D9: Réf YS3VET - Heure limite enregistrement: 19:20 (GVA T1) | E9: 24h avant 27/04
A10: ☐ | B10: Claudeane | C10: ⚠️ Acheter bagage soute SWISS! | D10: Economy Light = 0 bagage soute! Acheter en ligne SWISS.com | E10: DÈS QUE POSSIBLE
A11: ☐ | B11: Claudio | C11: Check-in TAP TP941+TP35 | D11: Réf XR2CPW - Sélectionner sièges aller | E11: 24h avant 23/05
A12: ☐ | B12: Claudio | C12: ⚠️ Vérifier bagage soute TAP | D12: Confirmation dit 0 soute. Vérifier/acheter sur TAP. | E12: DÈS QUE POSSIBLE
A13: ☐ | B13: Claud./Lucil./Jhem. | C13: ⚠️ Confirmer vols Azul (EN ESPERA) | D13: NOUVEAU: MJ5NQC (MAB→BEL) + ON3LQT (BEL→FOR). Sièges OK (11D/E/F + 11A/B/C). Bagages = 0!
A14: HÉBERGEMENTS
A15: ☐ | B15: Claudio | C15: ⚠️ Payer 50% Encontro do Sol | D15: 50% à payer 15j avant annul. (24/04). Deadline: 09/04/2026. Contacter +55 85 3031 6222 | E15: Avant 09/04 ⚠️
A16: ☐ | B16: Claudio | C16: ⚠️ Vérifier conditions ASAS DEL MAR | D16: Si 50% prépaiement: payer avant le 04/05/2026 (15j avant annul. 19/05) | E16: Avant 04/05
A17: ☐ | B17: Claudio | C17: ⚠️ Payer 50% Pousada Bangalô | D17: 50% à payer 15j avant annul. (26/05). Deadline: 11/05/2026. Réf 5620.348.709 | E17: Avant 11/05
A18: ☐ | B18: Tous | C18: ⚠️ RÉSERVER 2 NUITS (03/06-05/06)! | D18: Pousada Bangalô couvre 01-03/06. TROU restant: 2 nuits avant vol retour 05/06! | E18: URGENT!
A19: TRANSPORT
A20: ☐ | B20: Claud./Lucil./Jhem. | C20: ⚠️ Transport Ourilândia → Marabá | D20: Accès aéroport MAB pour vol Azul du 25/05 | E20: Avant 25/05
A21: ☐ | B21: Claudio | C21: Télécharger app Localiza (FAST) | D21: Retirada Digital sans passer par le comptoir | E21: Avant 23/05

Sheet 📞 Contacts & Adresses
A1: 📞 CONTACTS & ADRESSES UTILES
A3: Organisme / Hôtel | B3: Téléphone | C3: Adresse | D3: Notes
A4: COMPAGNIES AÉRIENNES
A5: SWISS Service Center | B5: +41 (0) 848 700 700 | C5: swiss.com/webcheckin | D5: Réf YS3VET (Claudeane)
A6: TAP Portugal | B6: flytap.com | C6: - | D6: Réf XR2CPW (Claudio) / XR85TH (Claudeane)
A7: Azul Linhas Aéreas | B7: 4003-1118 (BR) / 0800 887 1118 | C7: voeazul.com.br | D7: Réf MJ5NQC (MAB→BEL) + ON3LQT (BEL→FOR) + TNG1NT/AKE4YZ (SP→Ouril.)
A8: Booking.com (assistance FR) | B8: 0445 111 635 | C8: your.booking.com | D8: Depuis étranger: +33 1 57 32 92 09
A10: HÔTELS
A11: Free Palace Hotel (São Paulo) | B11: +55 11 3271 8596 | C11: RUA TAMANDARE 246, Liberdade, São Paulo, CEP 01525-000 | D11: GPS: S 023° 33.693, W 46° 37.977
A12: Maly Boutique Hotel (Fortaleza) | B12: +55 85 99111 0568 | C12: Av. Clóvis Arrais Maia 2790, Praia do Futuro I, CEP 60183-692 | D12: GPS: S 003° 43.880, W 38° 27.466
A13: Hotel Encontro do Sol (Fortaleza) | B13: +55 85 3031 6222 | C13: Rua Monsenhor Bruno 122, Meireles, CEP 60155190 | D13: GPS: S 003° 43.418, W 38° 30.401
A14: ASAS DEL MAR (Canoa Quebrada) | B14: +55 85 99856 8461 | C14: DT SITIO ESTEVAO CANOA QUEBRADA, Nº 3207, CEP 62800-000 | D14: GPS: S 004° 31.671, W 37° 41.874
A15: Pousada Bangalô (Jericoacoara) | B15: +55 88 99904 5258 | C15: Rua Novo Jeri, S/N, Jericoacoara, CEP 62598-000 | D15: GPS: S 002° 47.867, W 40° 30.843
A17: LOCATION VOITURE
A18: Localiza Rent a Car | B18: App Localiza (FAST) | C18: AV SENADOR CARLOS JEREISSATI 21, SERRINHA, FORTALEZA, CE | D18: Réf MO49499YVQBC - Agence aéroport 24h/24
A20: URGENCES BRÉSIL
A21: Police (Polícia Militar) | B21: 190
A22: SAMU (ambulance) | B22: 192
A23: Pompiers (Bombeiros) | B23: 193
A24: Ambassade/Consulat Suisse | B24: +55 61 3443 5500 | C24: Brasília | D24: Claudio: +41762470577

Sheet 📄 Description HTML
A1: 📄 DESCRIPTION COMPLÈTE DU CLASSEUR — VOYAGE BRÉSIL 2026 (MÀJ 21/02/2026)
A2: Source unique: 🗄️ BD Source. Tous les onglets sont liés par formules.
A4: ══════════════════════════════════════════════════════════════
A5: MÉTA-INFORMATIONS
A6: ══════════════════════════════════════════════════════════════
A7: Voyageur | B7: Rôle | C7: Dates | D7: Retour par
A8: Claudeane | B8: Épouse (brésilienne) 🎀 | C8: 27/04 → 06/06 | D8: ✈️ Avion
A9: Claudio | B9: Voyageur principal 👔 | C9: 23/05 → 06/06 | D9: ✈️ Avion
A10: Lucileide | B10: Sœur de Claudeane | C10: ~25/05 → après 06/06 | D10: 🚌 Bus
A11: Jhemerson | B11: Neveu | C11: ~25/05 → après 06/06 | D11: 🚌 Bus
A13: Devise | B13: Taux de change | C13: Note
A14: CHF / BRL | B14: 1 CHF = 6.7 BRL | C14: Modifiable dans BD Source B50
A16: Couleur | B16: Code Hex | C16: Usage
A17: ■ | B17: #1F4E79 | C17: Headers principaux
A18: ■ | B18: #2E75B6 | C18: Headers hôtels + Claudio
A19: ■ | B19: #E74C8B | C19: Claudeane (Gantt)
A20: ■ | B20: #4472C4 | C20: Headers BD Source
A21: ■ | B21: #FFC7CE | C21: Fond alertes urgentes
A23: ══════════════════════════════════════════════════════════════
A24: ONGLET: 📋 Logistique Vols (7 vols) — lié à BD Source
A25: ══════════════════════════════════════════════════════════════
A26: N° | B26: Passager(s) | C26: Itinéraire | D26: Date Dép | E26: Heure Dép | F26: Compagnie
A27: V1 | B27: Claudeane | C27: GVA → ZRH → GRU | D27: 27/04/2026 | E27: 0.83680556 | F27: SWISS
A28: V2 | B28: Claudeane | C28: VCP → BEL → Ourilândia | D28: 46208 | E28: 0.90625 | F28: Azul/Trip.com
A29: V3 | B29: Claudio | C29: GVA → Lisbonne → FOR | D29: 23/05/2026 | E29: 0.54166667 | F29: TAP Portugal
A30: V4 | B30: Claudio | C30: FOR → Lisbonne → GVA | D30: 46148 | E30: 0.95138889 | F30: TAP Portugal
A31: V5 | B31: Claudeane | C31: FOR → Lisbonne → GVA | D31: 46148 | E31: 0.95138889 | F31: TAP Portugal
A32: V6 | B32: Claud.+Lucil.+Jhem. | C32: MAB → BEL | D32: 25/05/2026 | E32: 0.61805556 | F32: Azul
A33: V7 | B33: Claud.+Lucil.+Jhem. | C33: BEL → FOR | D33: 25/05/2026 | E33: 0.75 | F33: Azul
A35: N° | B35: Date Arrivée | C35: Heure Arr | D35: Réf. | E35: Prix CHF | F35: Prix BRL
A36: V1 | B36: 28/04/2026 | C36: 0.22569444 | D36: YS3VET | E36: 290.15 | F36: —
A37: V2 | B37: 46239 | C37: 0.40625 | D37: TNG1NT/AKE4YZ | E37: 311.8 | F37: —
A38: V3 | B38: 23/05/2026 | C38: 0.88888889 | D38: XR2CPW | E38: 845.81 (A/R) | F38: —
A39: V4 | B39: 46179 | C39: 0.72916667 | D39: XR2CPW | E39: inclus A/R | F39: —
A40: V5 | B40: 46179 | C40: 0.72916667 | D40: XR85TH | E40: 552.15 | F40: —
A41: V6 | B41: 25/05/2026 | C41: 0.66319444 | D41: MJ5NQC | E41: — | F41: 1 300.17
A42: V7 | B42: 25/05/2026 | C42: 0.82986111 | D42: ON3LQT | E42: — | F42: 799.14
A44: N° | B44: Bagage Cabine | C44: Bagage Soute | D44: Sièges | E44: Statut | F44: Notes
A45: V1 | B45: 1 main (8kg) | C45: ⚠️ 0 SOUTE | D45: Non sélect. | E45: ✅ Payé MC****4753 | F45: Economy Light
A46: V2 | B46: 1 pers+1 cab (10kg) | C46: ✅ 1 soute (23kg) | D46: Non sélect. | E46: ⚠️ En Espera | F46: Escale Belém
...
